Workbook

Sheet Main
A1: Land (NL) | B1: Country | C1: CountryCode | D1: Countrycode 3 | E1: Currency | F1: Currency Code 3 dig | G1: Language | H1: Lang. in CM | I1: Phone nr | J1: Web | K1: Continent | L1: Region 1 | M1: Region 2
A2: Algerije | B2: Algeria | C2: DZ | D2: DZA | E2: Algerian Dinar | F2: DZD | G2: AR | H2: EN | I2: +213 | J2: =_xlfn.XLOOKUP(C2,'ISO overview'!A:A,'ISO overview'!J:J) -> .dz | K2: Africa | L2: Northern Africa | M2: =L2 -> Northern Africa
A3: Egypte | B3: Egypt | C3: EG | D3: EGY | E3: Egyptian Pound | F3: EGP | G3: AR | H3: EN | I3: +20 | J3: =_xlfn.XLOOKUP(C3,'ISO overview'!A:A,'ISO overview'!J:J) -> .eg | K3: Africa | L3: Northern Africa | M3: =L3 -> Northern Africa
A4: Libië | B4: Libyan Arab Jamahiriya | C4: LY | D4: LBY | E4: Libyan Dinar | F4: LYD | G4: AR | H4: EN | I4: +218 | J4: =_xlfn.XLOOKUP(C4,'ISO overview'!A:A,'ISO overview'!J:J) -> .ly | K4: Africa | L4: Northern Africa | M4: =L4 -> Northern Africa
A5: Marokko | B5: Morocco | C5: MA | D5: MAR | E5: Dirham | F5: MAD | G5: AR | H5: EN | I5: +212 | J5: =_xlfn.XLOOKUP(C5,'ISO overview'!A:A,'ISO overview'!J:J) -> .ma | K5: Africa | L5: Northern Africa | M5: =L5 -> Northern Africa
A6: Soedan | B6: Sudan | C6: SD | D6: SDN | E6: Dinar | F6: SDG | G6: AR | H6: EN | I6: +249 | J6: =_xlfn.XLOOKUP(C6,'ISO overview'!A:A,'ISO overview'!J:J) -> .sd | K6: Africa | L6: Northern Africa | M6: =L6 -> Northern Africa
A7: Tunesië | B7: Tunisia | C7: TN | D7: TUN | E7: Tunisian Dinar | F7: TND | G7: AR | H7: EN | I7: +216 | J7: =_xlfn.XLOOKUP(C7,'ISO overview'!A:A,'ISO overview'!J:J) -> .tn | K7: Africa | L7: Northern Africa | M7: =L7 -> Northern Africa
B8: Western Sahara | C8: EH | D8: ESH | E8: Dirham | F8: MAD | G8: AR | H8: EN | I8: +212 | J8: =_xlfn.XLOOKUP(C8,'ISO overview'!A:A,'ISO overview'!J:J) -> .eh | K8: Africa | L8: Northern Africa | M8: =L8 -> Northern Africa
B9: British Indian Ocean Territory | C9: IO | D9: IOT | E9: USD | F9: USD | G9: EN | H9: EN | I9: +246 | J9: =_xlfn.XLOOKUP(C9,'ISO overview'!A:A,'ISO overview'!J:J) -> .io | K9: Africa | L9: Sub-Saharan Africa | M9: Eastern Africa
A10: Burundi | B10: Burundi | C10: BI | D10: BDI | E10: Burundi Franc | F10: BIF | G10: FR | H10: FR | I10: +257 | J10: =_xlfn.XLOOKUP(C10,'ISO overview'!A:A,'ISO overview'!J:J) -> .bi | K10: Africa | L10: Sub-Saharan Africa | M10: Eastern Africa
A11: de Comore | B11: Comoros | C11: KM | D11: COM | E11: Comoran Franc | F11: KMF | G11: AR | H11: EN | I11: +269 | J11: =_xlfn.XLOOKUP(C11,'ISO overview'!A:A,'ISO overview'!J:J) -> .km | K11: Africa | L11: Sub-Saharan Africa | M11: Eastern Africa
A12: Djibouti | B12: Djibouti | C12: DJ | D12: DJI | E12: Djiboutian Franc | F12: DJF | G12: FR | H12: FR | I12: +253 | J12: =_xlfn.XLOOKUP(C12,'ISO overview'!A:A,'ISO overview'!J:J) -> .dj | K12: Africa | L12: Sub-Saharan Africa | M12: Eastern Africa
A13: Eritrea | B13: Eritrea | C13: ER | D13: ERI | E13: Ethiopian Birr | F13: ETB | G13: AA | H13: EN | I13: +291 | J13: =_xlfn.XLOOKUP(C13,'ISO overview'!A:A,'ISO overview'!J:J) -> .er | K13: Africa | L13: Sub-Saharan Africa | M13: Eastern Africa
A14: Ethiopië | B14: Ethiopia | C14: ET | D14: ETH | E14: Ethiopian Birr | F14: ETB | G14: AM | H14: EN | I14: +251 | J14: =_xlfn.XLOOKUP(C14,'ISO overview'!A:A,'ISO overview'!J:J) -> .et | K14: Africa | L14: Sub-Saharan Africa | M14: Eastern Africa
B15: French Southern Territories | C15: TF | D15: ATF | E15: Euros | F15: EUR | G15: FR | H15: FR | I15: + | J15: =_xlfn.XLOOKUP(C15,'ISO overview'!A:A,'ISO overview'!J:J) -> .tf | K15: Africa | L15: Sub-Saharan Africa | M15: Eastern Africa
A16: Kenia | B16: Kenya | C16: KE | D16: KEN | E16: Kenyan Shilling | F16: KES | G16: EN | H16: EN | I16: +254 | J16: =_xlfn.XLOOKUP(C16,'ISO overview'!A:A,'ISO overview'!J:J) -> .ke | K16: Africa | L16: Sub-Saharan Africa | M16: Eastern Africa
A17: Madagaskar | B17: Madagascar | C17: MG | D17: MDG | E17: Malagasy Franc | F17: MGA | G17: FR | H17: FR | I17: +261 | J17: =_xlfn.XLOOKUP(C17,'ISO overview'!A:A,'ISO overview'!J:J) -> .mg | K17: Africa | L17: Sub-Saharan Africa | M17: Eastern Africa
A18: Malawi | B18: Malawi | C18: MW | D18: MWI | E18: Malawian Kwacha | F18: MWK | G18: NY | H18: EN | I18: +265 | J18: =_xlfn.XLOOKUP(C18,'ISO overview'!A:A,'ISO overview'!J:J) -> .mw | K18: Africa | L18: Sub-Saharan Africa | M18: Eastern Africa
A19: Mauritius | B19: Mauritius | C19: MU | D19: MUS | E19: Mauritian Rupee | F19: MUR | G19: EN | H19: EN | I19: +230 | J19: =_xlfn.XLOOKUP(C19,'ISO overview'!A:A,'ISO overview'!J:J) -> .mu | K19: Africa | L19: Sub-Saharan Africa | M19: Eastern Africa
B20: Mayotte | C20: YT | D20: MYT | E20: Euros | F20: EUR | G20: FR | H20: FR | I20: +262 | J20: =_xlfn.XLOOKUP(C20,'ISO overview'!A:A,'ISO overview'!J:J) -> .yt | K20: Africa | L20: Sub-Saharan Africa | M20: Eastern Africa
A21: Mozambique | B21: Mozambique | C21: MZ | D21: MOZ | E21: Metical | F21: MZN | G21: PT | H21: PT | I21: +258 | J21: =_xlfn.XLOOKUP(C21,'ISO overview'!A:A,'ISO overview'!J:J) -> .mz | K21: Africa | L21: Sub-Saharan Africa | M21: Eastern Africa
B22: Reunion | C22: RE | D22: REU | E22: Euros | F22: EUR | G22: FR | H22: FR | I22: +262 | J22: =_xlfn.XLOOKUP(C22,'ISO overview'!A:A,'ISO overview'!J:J) -> .re | K22: Africa | L22: Sub-Saharan Africa | M22: Eastern Africa
A23: Rwanda | B23: Rwanda | C23: RW | D23: RWA | E23: Rwanda Franc | F23: RWF | G23: RW | H23: EN | I23: +250 | J23: =_xlfn.XLOOKUP(C23,'ISO overview'!A:A,'ISO overview'!J:J) -> .rw | K23: Africa | L23: Sub-Saharan Africa | M23: Eastern Africa
A24: de Seychelle | B24: Seychelles | C24: SC | D24: SYC | E24: Rupee | F24: SCR | G24: EN | H24: EN | I24: +248 | J24: =_xlfn.XLOOKUP(C24,'ISO overview'!A:A,'ISO overview'!J:J) -> .sc | K24: Africa | L24: Sub-Saharan Africa | M24: Eastern Africa
A25: Somalië | B25: Somalia | C25: SO | D25: SOM | E25: Shilling | F25: SOS | G25: SO | H25: EN | I25: +252 | J25: =_xlfn.XLOOKUP(C25,'ISO overview'!A:A,'ISO overview'!J:J) -> .so | K25: Africa | L25: Sub-Saharan Africa | M25: Eastern Africa
A26: Tanzania | B26: Tanzania | C26: TZ | D26: TZA | E26: Shilling | F26: TZS | G26: SW | H26: EN | I26: +255 | J26: =_xlfn.XLOOKUP(C26,'ISO overview'!A:A,'ISO overview'!J:J) -> .tz | K26: Africa | L26: Sub-Saharan Africa | M26: Eastern Africa
A27: Oeganda | B27: Uganda | C27: UG | D27: UGA | E27: Shilling | F27: UGX | G27: EN | H27: EN | I27: +256 | J27: =_xlfn.XLOOKUP(C27,'ISO overview'!A:A,'ISO overview'!J:J) -> .ug | K27: Africa | L27: Sub-Saharan Africa | M27: Eastern Africa
A28: Zambia Z | B28: Zambia | C28: ZM | D28: ZMB | E28: Kwacha | F28: ZMK | G28: EN | H28: EN | I28: +260 | J28: =_xlfn.XLOOKUP(C28,'ISO overview'!A:A,'ISO overview'!J:J) -> .zm | K28: Africa | L28: Sub-Saharan Africa | M28: Eastern Africa
A29: Zimbabwe | B29: Zimbabwe | C29: ZW | D29: ZWE | E29: Zimbabwe Dollar | F29: ZWD | G29: EN | H29: EN | I29: +263 | J29: =_xlfn.XLOOKUP(C29,'ISO overview'!A:A,'ISO overview'!J:J) -> .zw | K29: Africa | L29: Sub-Saharan Africa | M29: Eastern Africa
A30: Angola | B30: Angola | C30: AO | D30: AGO | E30: Angolan kwanza | F30: AOA | G30: PT | H30: PT | I30: +244 | J30: =_xlfn.XLOOKUP(C30,'ISO overview'!A:A,'ISO overview'!J:J) -> .ao | K30: Africa | L30: Sub-Saharan Africa | M30: Middle Africa
A31: Kameroen | B31: Cameroon | C31: CM | D31: CMR | E31: CFA Franc BEAC | F31: XAF | G31: EN | H31: EN | I31: +237 | J31: =_xlfn.XLOOKUP(C31,'ISO overview'!A:A,'ISO overview'!J:J) -> .cm | K31: Africa | L31: Sub-Saharan Africa | M31: Middle Africa
A32: de Centraal-Afrikaanse Republie | B32: Central African Republic | C32: CF | D32: CAF | E32: CFA Franc BEAC | F32: XAF | G32: FR | H32: FR | I32: +236 | J32: =_xlfn.XLOOKUP(C32,'ISO overview'!A:A,'ISO overview'!J:J) -> .cf | K32: Africa | L32: Sub-Saharan Africa | M32: Middle Africa
A33: Tsjaad | B33: Chad | C33: TD | D33: TCD | E33: CFA Franc BEAC | F33: XAF | G33: FR | H33: FR | I33: +235 | J33: =_xlfn.XLOOKUP(C33,'ISO overview'!A:A,'ISO overview'!J:J) -> .td | K33: Africa | L33: Sub-Saharan Africa | M33: Middle Africa
A34: Congo-Kinshasa | B34: Congo (Kinshasa) | C34: CD | D34: COD | E34: Congolese Frank | F34: CDF | G34: FR | H34: FR | I34: +243 | J34: =_xlfn.XLOOKUP(C34,'ISO overview'!A:A,'ISO overview'!J:J) -> .cd | K34: Africa | L34: Sub-Saharan Africa | M34: Middle Africa
... A57: Nigeria | B57: Nigeria | C57: NG | D57: NGA | E57: Naira | F57: NGN | G57: EN | H57: EN | I57: +234 | J57: =_xlfn.XLOOKUP(C57,'ISO overview'!A:A,'ISO overview'!J:J) -> .ng | K57: Africa | L57: Sub-Saharan Africa | M57: Western Africa
B58: Saint Helena | C58: SH | D58: SHN | E58: Saint Helena pound | F58: GBP | G58: EN | H58: EN | I58: +290 | J58: =_xlfn.XLOOKUP(C58,'ISO overview'!A:A,'ISO overview'!J:J) -> .sh | K58: Africa | L58: Sub-Saharan Africa | M58: Western Africa
A59: Senegal | B59: Senegal | C59: SN | D59: SEN | E59: CFA Franc BCEAO | F59: XOF | G59: FR | H59: FR | I59: +221 | J59: =_xlfn.XLOOKUP(C59,'ISO overview'!A:A,'ISO overview'!J:J) -> .sn | K59: Africa | L59: Sub-Saharan Africa | M59: Western Africa
A60: Sierra Leone | B60: Sierra Leone | C60: SL | D60: SLE | E60: Leone | F60: SLL | G60: EN | H60: EN | I60: +232 | J60: =_xlfn.XLOOKUP(C60,'ISO overview'!A:A,'ISO overview'!J:J) -> .sl | K60: Africa | L60: Sub-Saharan Africa | M60: Western Africa
A61: Togo | B61: Togo | C61: TG | D61: TGO | E61: CFA Franc BCEAO | F61: XOF | G61: FR | H61: FR | I61: +228 | J61: =_xlfn.XLOOKUP(C61,'ISO overview'!A:A,'ISO overview'!J:J) -> .tg | K61: Africa | L61: Sub-Saharan Africa | M61: Western Africa
B62: Antarctica | C62: AQ | D62: ATA | E62: Antarctican dollar | F62: AQD | G62: EN | H62: EN | I62: + | J62: =_xlfn.XLOOKUP(C62,'ISO overview'!A:A,'ISO overview'!J:J) -> .aq | K62: Antarctica | L62: Antarctica | M62: =L62 -> Antarctica
...

Sheet Countrycode
A1: Country | B1: Alpha-2 code | C1: Alpha-3 code | D1: Numeric
A2: Afghanistan | B2: AF | C2: AFG | D2: 4
A3: Åland Islands | B3: AX | C3: ALA | D3: 248
A4: Albania | B4: AL | C4: ALB | D4: 8
A5: Algeria | B5: DZ | C5: DZA | D5: 12
A6: American Samoa | B6: AS | C6: ASM | D6: 16
A7: Andorra | B7: AD | C7: AND | D7: 20
A8: Angola | B8: AO | C8: AGO | D8: 24
A9: Anguilla | B9: AI | C9: AIA | D9: 660
A10: Antarctica | B10: AQ | C10: ATA | D10: 10
A11: Antigua and Barbuda | B11: AG | C11: ATG | D11: 28
A12: Argentina | B12: AR | C12: ARG | D12: 32
A13: Armenia | B13: AM | C13: ARM | D13: 51
... A250: Zimbabwe | B250: ZW | C250: ZWE | D250: 716

Sheet Continent
A1: World | B1: Continent | C1: Subregrion | D1: Subsub region | E1: Code | F1: Count | H1: No | I1: Country or Area | J1: ISO-alpha3 Code | K1: M49 Code | L1: Continent | M1: Region 1 | N1: Region 2
B2: Africa | E2: 2 | F2: 60 | H2: 13 | I2: Aruba | J2: ABW | K2: 533 | L2: North America | M2: Caribbean | N2: Latin America and the Caribbean
C3: Northern Africa | E3: 15 | F3: 7 | H3: 1 | I3: Afghanistan | J3: AFG | K3: 4 | L3: Asia | M3: Southern Asia
C4: Sub-Saharan Africa | E4: 202 | F4: 53 | H4: 7 | I4: Angola | J4: AGO | K4: 24 | L4: Africa | M4: Middle Africa | N4: Sub-Saharan Africa
D5: Eastern Africa | E5: 14 | F5: 22 | H5: 8 | I5: Anguilla | J5: AIA | K5: 660 | L5: North America | M5: Caribbean | N5: Latin America and the Caribbean
D6: Middle Africa | E6: 17 | F6: 9 | H6: 2 | I6: Åland Islands | J6: ALA | K6: 248 | L6: Europe | M6: Northern Europe
D7: Southern Africa | E7: 18 | F7: 5 | H7: 3 | I7: Albania | J7: ALB | K7: 8 | L7: Europe | M7: Southern Europe
D8: Western Africa | E8: 11 | F8: 17 | H8: 6 | I8: Andorra | J8: AND | K8: 20 | L8: Europe | M8: Southern Europe
B9: Americas | E9: 19 | F9: 57 | H9: 234 | I9: United Arab Emirates | J9: ARE | K9: 784 | L9: Asia | M9: Western Asia
C10: Latin America and the Caribbean | E10: 419 | F10: 52 | H10: 11 | I10: Argentina | J10: ARG | K10: 32 | L10: South America | M10: South America | N10: Latin America and the Caribbean
D11: Caribbean | E11: 29 | F11: 28 | H11: 12 | I11: Armenia | J11: ARM | K11: 51 | L11: Asia | M11: Western Asia
D12: Central America | E12: 13 | F12: 8 | H12: 5 | I12: American Samoa | J12: ASM | K12: 16 | L12: Oceania | M12: Polynesia
D13: South America | E13: 5 | F13: 16 | H13: 9 | I13: Antarctica | J13: ATA | K13: 10 | L13: Antarctica | M13: Antarctica
C14: Northern America | E14: 21 | F14: 5 | H14: 84 | I14: French Southern Territories | J14: ATF | K14: 260 | L14: Africa | M14: Eastern Africa | N14: Sub-Saharan Africa
B15: Antarctica | E15: 10 | F15: 1 | H15: 10 | I15: Antigua and Barbuda | J15: ATG | K15: 28 | L15: North America | M15: Caribbean | N15: Latin America and the Caribbean
B16: Asia | E16: 142 | F16: 50 | H16: 14 | I16: Australia | J16: AUS | K16: 36 | L16: Oceania | M16: Australia and New Zealand
C17: Central Asia | E17: 143 | F17: 5 | H17: 15 | I17: Austria | J17: AUT | K17: 40 | L17: Europe | M17: Western Europe
C18: Eastern Asia | E18: 30 | F18: 7 | H18: 16 | I18: Azerbaijan | J18: AZE | K18: 31 | L18: Asia | M18: Western Asia
C19: South-eastern Asia | E19: 35 | F19: 11 | H19: 38 | I19: Burundi | J19: BDI | K19: 108 | L19: Africa | M19: Eastern Africa | N19: Sub-Saharan Africa
C20: Southern Asia | E20: 34 | F20: 9 | H20: 22 | I20: Belgium | J20: BEL | K20: 56 | L20: Europe | M20: Western Europe
C21: Western Asia | E21: 145 | F21: 18 | H21: 24 | I21: Benin | J21: BEN | K21: 204 | L21: Africa | M21: Western Africa | N21: Sub-Saharan Africa
B22: Europe | E22: 150 | F22: 52 | H22: 28 | I22: Bonaire, Sint Eustatius and Saba | J22: BES | K22: 535 | L22: North America | M22: Caribbean | N22: Latin America and the Caribbean
C23: Eastern Europe | E23: 151 | F23: 10 | H23: 37 | I23: Burkina Faso | J23: BFA | K23: 854 | L23: Africa | M23: Western Africa | N23: Sub-Saharan Africa
C24: Northern Europe | E24: 154 | F24: 17 | H24: 19 | I24: Bangladesh | J24: BGD | K24: 50 | L24: Asia | M24: Southern Asia
D25: Channel Islands | E25: 830 | F25: 3 | H25: 36 | I25: Bulgaria | J25: BGR | K25: 100 | L25: Europe | M25: Eastern Europe
C26: Southern Europe | E26: 39 | F26: 16 | H26: 18 | I26: Bahrain | J26: BHR | K26: 48 | L26: Asia | M26: Western Asia
C27: Western Europe | E27: 155 | F27: 9 | H27: 17 | I27: Bahamas | J27: BHS | K27: 44 | L27: North America | M27: Caribbean | N27: Latin America and the Caribbean
B28: Oceania | E28: 9 | F28: 29 | H28: 29 | I28: Bosnia and Herzegovina | J28: BIH | K28: 70 | L28: Europe | M28: Southern Europe
C29: Australia and New Zealand | E29: 53 | F29: 6 | H29: 186 | I29: Saint Barthélemy | J29: BLM | K29: 652 | L29: North America | M29: Caribbean | N29: Latin America and the Caribbean
C30: Melanesia | E30: 54 | F30: 5 | H30: 21 | I30: Belarus | J30: BLR | K30: 112 | L30: Europe | M30: Eastern Europe
C31: Micronesia | E31: 57 | F31: 8 | H31: 23 | I31: Belize | J31: BLZ | K31: 84 | L31: North America | M31: Central America | N31: Latin America and the Caribbean
C32: Polynesia | E32: 61 | F32: 10 | H32: 25 | I32: Bermuda | J32: BMU | K32: 60 | L32: North America | M32: Northern America
H33: 27 | I33: Bolivia (Plurinational State of) | J33: BOL | K33: 68 | L33: South America | M33: South America | N33: Latin America and the Caribbean
H34: 32 | I34: Brazil | J34: BRA | K34: 76 | L34: South America | M34: South America | N34: Latin America and the Caribbean
H35: 20 | I35: Barbados | J35: BRB | K35: 52 | L35: North America | M35: Caribbean | N35: Latin America and the Caribbean
H36: 35 | I36: Brunei Darussalam | J36: BRN | K36: 96 | L36: Asia | M36: South-eastern Asia
H37: 26 | I37: Bhutan | J37: BTN | K37: 64 | L37: Asia | M37: Southern Asia
H38: 31 | I38: Bouvet Island | J38: BVT | K38: 74 | L38: South America | M38: South America | N38: Latin America and the Caribbean
H39: 30 | I39: Botswana | J39: BWA | K39: 72 | L39: Africa | M39: Southern Africa | N39: Sub-Saharan Africa
H40: 44 | I40: Central African Republic | J40: CAF | K40: 140 | L40: Africa | M40: Middle Africa | N40: Sub-Saharan Africa
...

Sheet Sheet4
A1: Langcode in CM | B1: Currendcy in CM
A2: DE | B2: ANG
A3: EN | B3: AUD
A4: ES | B4: BGN
A5: FR | B5: BRL
A6: IT | B6: CAD
A7: NL | B7: CHF
A8: PT | B8: CNY
B9: CZK
B10: DKK
B11: EUR
B12: GBP
B13: HKD
B14: HRK
B15: HUF
B16: IDR
B17: ILS
B18: INR
B19: JPY
B20: KRW
... B35: ZAR

Sheet ISO overview
A1: #ISO | B1: ISO3 | C1: ISO-Numeric | D1: fips | E1: Country | F1: Capital | G1: Area(in sq km) | H1: Population | I1: Continent | J1: tld | K1: CurrencyCode | L1: CurrencyName | M1: Phone with plus | N1: Postal Code Format | O1: Postal Code Regex | P1: Languages | Q1: Official language | R1: geonameid | S1: neighbours | T1: EquivalentFipsCode
A2: AD | B2: AND | C2: 20 | D2: AN | E2: Andorra | F2: Andorra la Vella | G2: 468 | H2: 77006 | I2: EU | J2: .ad | K2: EUR | L2: Euro | M2: +376 | N2: AD### | O2: ^(?:AD)*(\d{3})$ | P2: ca | Q2: ca | R2: 3041565 | S2: ES,FR
A3: AE | B3: ARE | C3: 784 | D3: AE | E3: United Arab Emirates | F3: Abu Dhabi | G3: 82880 | H3: 9630959 | I3: AS | J3: .ae | K3: AED | L3: Dirham | M3: +971 | P3: ar-AE,fa,en,hi,ur | Q3: ar | R3: 290557 | S3: SA,OM
A4: AF | B4: AFG | C4: 4 | D4: AF | E4: Afghanistan | F4: Kabul | G4: 647500 | H4: 37172386 | I4: AS | J4: .af | K4: AFN | L4: Afghani | M4: +93 | P4: fa-AF,ps,uz-AF,tk | Q4: fa | R4: 1149361 | S4: TM,CN,IR,TJ,PK,UZ
A5: AG | B5: ATG | C5: 28 | D5: AC | E5: Antigua and Barbuda | F5: St. John's | G5: 443 | H5: 96286 | I5: NA | J5: .ag | K5: XCD | L5: Dollar | M5: +1-268 | P5: en-AG | Q5: en | R5: 3576396
A6: AI | B6: AIA | C6: 660 | D6: AV | E6: Anguilla | F6: The Valley | G6: 102 | H6: 13254 | I6: NA | J6: .ai | K6: XCD | L6: Dollar | M6: +1-264 | P6: en-AI | Q6: en | R6: 3573511
A7: AL | B7: ALB | C7: 8 | D7: AL | E7: Albania | F7: Tirana | G7: 28748 | H7: 2866376 | I7: EU | J7: .al | K7: ALL | L7: Lek | M7: +355 | N7: #### | O7: ^(\d{4})$ | P7: sq,el | Q7: sq | R7: 783754 | S7: MK,GR,ME,RS,XK
A8: AM | B8: ARM | C8: 51 | D8: AM | E8: Armenia | F8: Yerevan | G8: 29800 | H8: 2951776 | I8: AS | J8: .am | K8: AMD | L8: Dram | M8: +374 | N8: ###### | O8: ^(\d{6})$ | P8: hy | Q8: hy | R8: 174982 | S8: GE,IR,AZ,TR
A9: AO | B9: AGO | C9: 24 | D9: AO | E9: Angola | F9: Luanda | G9: 1246700 | H9: 30809762 | I9: AF | J9: .ao | K9: AOA | L9: Kwanza | M9: +244 | P9: pt-AO | Q9: pt | R9: 3351879 | S9: CD,NA,ZM,CG
A10: AQ | B10: ATA | C10: 10 | D10: AY | E10: Antarctica | G10: 14000000 | H10: 0 | I10: AN | J10: .aq | M10: + | R10: 6697173
A11: AR | B11: ARG | C11: 32 | D11: AR | E11: Argentina | F11: Buenos Aires | G11: 2766890 | H11: 44494502 | I11: SA | J11: .ar | K11: ARS | L11: Peso | M11: +54 | N11: @####@@@ | O11: ^[A-Z]?\d{4}[A-Z]{0,3}$ | P11: es-AR,en,it,de,fr,gn | Q11: es | R11: 3865483 | S11: CL,BO,UY,PY,BR
A12: AS | B12: ASM | C12: 16 | D12: AQ | E12: American Samoa | F12: Pago Pago | G12: 199 | H12: 55465 | I12: OC | J12: .as | K12: USD | L12: Dollar | M12: +1-684 | N12: #####-#### | O12: 96799 | P12: en-AS,sm,to | Q12: en | R12: 5880801
A13: AT | B13: AUT | C13: 40 | D13: AU | E13: Austria | F13: Vienna | G13: 83858 | H13: 8847037 | I13: EU | J13: .at | K13: EUR | L13: Euro | M13: +43 | N13: #### | O13: ^(\d{4})$ | P13: de-AT,hr,hu,sl | Q13: de | R13: 2782113 | S13: CH,DE,HU,SK,CZ,IT,SI,LI
A14: AU | B14: AUS | C14: 36 | D14: AS | E14: Australia | F14: Canberra | G14: 7686850 | H14: 24992369 | I14: OC | J14: .au | K14: AUD | L14: Dollar | M14: +61 | N14: #### | O14: ^(\d{4})$ | P14: en-AU | Q14: en | R14: 2077456
A15: AW | B15: ABW | C15: 533 | D15: AA | E15: Aruba | F15: Oranjestad | G15: 193 | H15: 105845 | I15: NA | J15: .aw | K15: AWG | L15: Guilder | M15: +297 | P15: nl-AW,pap,es,en | Q15: nl | R15: 3577279
A16: AX | B16: ALA | C16: 248 | E16: Aland Islands | F16: Mariehamn | G16: 1580 | H16: 26711 | I16: EU | J16: .ax | K16: EUR | L16: Euro | M16: +358-18 | N16: ##### | O16: ^(?:FI)*(\d{5})$ | P16: sv-AX | Q16: sv | R16: 661882 | T16: FI
A17: AZ | B17: AZE | C17: 31 | D17: AJ | E17: Azerbaijan | F17: Baku | G17: 86600 | H17: 9942334 | I17: AS | J17: .az | K17: AZN | L17: Manat | M17: +994 | N17: AZ #### | O17: ^(?:AZ)*(\d{4})$ | P17: az,ru,hy | Q17: az | R17: 587116 | S17: GE,IR,AM,TR,RU
A18: BA | B18: BIH | C18: 70 | D18: BK | E18: Bosnia and Herzegovina | F18: Sarajevo | G18: 51129 | H18: 3323929 | I18: EU | J18: .ba | K18: BAM | L18: Marka | M18: +387 | N18: ##### | O18: ^(\d{5})$ | P18: bs,hr-BA,sr-BA | Q18: bs | R18: 3277605 | S18: HR,ME,RS
A19: BB | B19: BRB | C19: 52 | D19: BB | E19: Barbados | F19: Bridgetown | G19: 431 | H19: 286641 | I19: NA | J19: .bb | K19: BBD | L19: Dollar | M19: +1-246 | N19: BB##### | O19: ^(?:BB)*(\d{5})$ | P19: en-BB | Q19: en | R19: 3374084
A20: BD | B20: BGD | C20: 50 | D20: BG | E20: Bangladesh | F20: Dhaka | G20: 144000 | H20: 161356039 | I20: AS | J20: .bd | K20: BDT | L20: Taka | M20: +880 | N20: #### | O20: ^(\d{4})$ | P20: bn-BD,en | Q20: bn | R20: 1210997 | S20: MM,IN
A21: BE | B21: BEL | C21: 56 | D21: BE | E21: Belgium | F21: Brussels | G21: 30510 | H21: 11422068 | I21: EU | J21: .be | K21: EUR | L21: Euro | M21: +32 | N21: #### | O21: ^(\d{4})$ | P21: nl-BE,fr-BE,de-BE | Q21: nl | R21: 2802361 | S21: DE,NL,LU,FR
A22: BF | B22: BFA | C22: 854 | D22: UV | E22: Burkina Faso | F22: Ouagadougou | G22: 274200 | H22: 19751535 | I22: AF | J22: .bf | K22: XOF | L22: Franc | M22: +226 | P22: fr-BF,mos | Q22: fr | R22: 2361809 | S22: NE,BJ,GH,CI,TG,ML
A23: BG | B23: BGR | C23: 100 | D23: BU | E23: Bulgaria | F23: Sofia | G23: 110910 | H23: 7000039 | I23: EU | J23: .bg | K23: BGN | L23: Lev | M23: +359 | N23: #### | O23: ^(\d{4})$ | P23: bg,tr-BG,rom | Q23: bg | R23: 732800 | S23: MK,GR,RO,TR,RS
A24: BH | B24: BHR | C24: 48 | D24: BA | E24: Bahrain | F24: Manama | G24: 665 | H24: 1569439 | I24: AS | J24: .bh | K24: BHD | L24: Dinar | M24: +973 | N24: ####|### | O24: ^(\d{3}\d?)$ | P24: ar-BH,en,fa,ur | Q24: ar | R24: 290291
A25: BI | B25: BDI | C25: 108 | D25: BY | E25: Burundi | F25: Gitega | G25: 27830 | H25: 11175378 | I25: AF | J25: .bi | K25: BIF | L25: Franc | M25: +257 | P25: fr-BI,rn | Q25: fr | R25: 433561 | S25: TZ,CD,RW
A26: BJ | B26: BEN | C26: 204 | D26: BN | E26: Benin | F26: Porto-Novo | G26: 112620 | H26: 11485048 | I26: AF | J26: .bj | K26: XOF | L26: Franc | M26: +229 | P26: fr-BJ | Q26: fr | R26: 2395170 | S26: NE,TG,BF,NG
A27: BL | B27: BLM | C27: 652 | D27: TB | E27: Saint Barthelemy | F27: Gustavia | G27: 21 | H27: 8450 | I27: NA | J27: .gp | K27: EUR | L27: Euro | M27: +590 | N27: ##### | O27: ^(\d{5})$ | P27: fr | Q27: fr | R27: 3578476
A28: BM | B28: BMU | C28: 60 | D28: BD | E28: Bermuda | F28: Hamilton | G28: 53 | H28: 63968 | I28: NA | J28: .bm | K28: BMD | L28: Dollar | M28: +1-441 | N28: @@ ## | O28: ^([A-Z]{2}\d{2})$ | P28: en-BM,pt | Q28: en | R28: 3573345
A29: BN | B29: BRN | C29: 96 | D29: BX | E29: Brunei | F29: Bandar Seri Begawan | G29: 5770 | H29: 428962 | I29: AS | J29: .bn | K29: BND | L29: Dollar | M29: +673 | N29: @@#### | O29: ^([A-Z]{2}\d{4})$ | P29: ms-BN,en-BN | Q29: ms | R29: 1820814 | S29: MY
A30: BO | B30: BOL | C30: 68 | D30: BL | E30: Bolivia | F30: Sucre | G30: 1098580 | H30: 11353142 | I30: SA | J30: .bo | K30: BOB | L30: Boliviano | M30: +591 | P30: es-BO,qu,ay | Q30: es | R30: 3923057 | S30: PE,CL,PY,BR,AR
A31: BQ | B31: BES | C31: 535 | E31: Bonaire, Saint Eustatius and Saba | G31: 328 | H31: 18012 | I31: NA | J31: .bq | K31: USD | L31: Dollar | M31: +599 | P31: nl,pap,en | Q31: nl | R31: 7626844
A32: BR | B32: BRA | C32: 76 | D32: BR | E32: Brazil | F32: Brasilia | G32: 8511965 | H32: 209469333 | I32: SA | J32: .br | K32: BRL | L32: Real | M32: +55 | N32: #####-### | O32: ^\d{5}-\d{3}$ | P32: pt-BR,es,en,fr | Q32: pt | R32: 3469034 | S32: SR,PE,BO,UY,GY,PY,GF,VE,CO,AR
A33: BS | B33: BHS | C33: 44 | D33: BF | E33: Bahamas | F33: Nassau | G33: 13940 | H33: 385640 | I33: NA | J33: .bs | K33: BSD | L33: Dollar | M33: +1-242 | P33: en-BS | Q33: en | R33: 3572887
A34: BT | B34: BTN | C34: 64 | D34: BT | E34: Bhutan | F34: Thimphu | G34: 47000 | H34: 754394 | I34: AS | J34: .bt | K34: BTN | L34: Ngultrum | M34: +975 | P34: dz | Q34: dz | R34: 1252634 | S34: CN,IN
A35: BV | B35: BVT | C35: 74 | D35: BV | E35: Bouvet Island | G35: 49 | H35: 0 | I35: AN | J35: .bv | K35: NOK | L35: Krone | M35: + | R35: 3371123
A36: BW | B36: BWA | C36: 72 | D36: BC | E36: Botswana | F36: Gaborone | G36: 600370 | H36: 2254126 | I36: AF | J36: .bw | K36: BWP | L36: Pula | M36: +267 | P36: en-BW,tn-BW | Q36: en | R36: 933860 | S36: ZW,ZA,NA
A37: BY | B37: BLR | C37: 112 | D37: BO | E37: Belarus | F37: Minsk | G37: 207600 | H37: 9485386 | I37: EU | J37: .by | K37: BYN | L37: Belarusian ruble | M37: +375 | N37: ###### | O37: ^(\d{6})$ | P37: be,ru | Q37: be | R37: 630336 | S37: PL,LT,UA,RU,LV
A38: BZ | B38: BLZ | C38: 84 | D38: BH | E38: Belize | F38: Belmopan | G38: 22966 | H38: 383071 | I38: NA | J38: .bz | K38: BZD | L38: Dollar | M38: +501 | P38: en-BZ,es | Q38: en | R38: 3582678 | S38: GT,MX
A39: CA | B39: CAN | C39: 124 | D39: CA | E39: Canada | F39: Ottawa | G39: 9984670 | H39: 37058856 | I39: NA | J39: .ca | K39: CAD | L39: Dollar | M39: +1 | N39: @#@ #@# | O39: ^([ABCEGHJKLMNPRSTVXY]\d[ABCEGHJKLMNPRSTVWXYZ]) ?(\d[ABCEGHJKLMNPRSTVWXYZ]\d)$ | P39: en-CA,fr-CA,iu | Q39: en | R39: 6251999 | S39: US
A40: CC | B40: CCK | C40: 166 | D40: CK | E40: Cocos Islands | F40: West Island | G40: 14 | H40: 628 | I40: AS | J40: .cc | K40: AUD | L40: Dollar | M40: +61 | P40: ms-CC,en | Q40: ms | R40: 1547376
...
